Feature: Python nodes
  Background: Project Setup
    Given the project 008_pure_python_models

  @TODO-postgres
  @TODO-fal
  @TODO-bigquery
  @TODO-snowflake
  @TODO-redshift
  @TODO-duckdb
  @TODO-athena
  Scenario: Run a project with Python nodes
    When the following command is invoked:
      """
      fal flow run --profiles-dir $profilesDir --project-dir $baseDir --exclude broken_model
      """
    Then the following models are calculated in order:
      | model_a | model_b | model_c.py | model_d | model_e.ipynb |
    Then the following scripts are ran:
      | model_a.after.py | model_b.before.py | model_c.after.py | model_e.pre_hook.py | model_e.post_hook.py | model_c.post_hook.py |

  Scenario: Run a project with Python nodes only selecting the Python model
    When the following command is invoked:
      """
      fal flow run --profiles-dir $profilesDir --project-dir $baseDir --select model_c
      """
    Then the following models are calculated in order:
      | model_c.py |
    And the following scripts are not ran:
      | model_c.after.py |
    And the following scripts are ran:
      | model_c.post_hook.py |
    And the script model_c.post_hook.py output file has the lines:
      | Status: success |

  @TODO-logging
  Scenario: Python model post hooks run even when model script fails
    When the following command is invoked:
      """
      fal flow run --profiles-dir $profilesDir --project-dir $baseDir --select broken_model
      """
    Then the following scripts are ran:
      | broken_model.post_hook.py |
    And the script broken_model.post_hook.py output file has the lines:
      | Status: error |
    And it throws an exception RuntimeError with message 'Error in scripts (model: models/staging/broken_model.py)'

  Scenario: Run a Python node without write to model should error
    Given the project 012_model_generation_error
    When the following command is invoked:
      """
      fal flow run --profiles-dir $profilesDir --project-dir $baseDir --select no_write_model
      """
    Then it throws an exception AssertionError with message 'There must be at least one write_to_model call in the Python Model'

  Scenario: Broken DBT model leads to corruption of the dependant Python model
    Given the project 014_broken_dbt_models
    When the following command is invoked:
      """
      fal flow run --profiles-dir $profilesDir --project-dir $baseDir --select get_data regular_model
      """
    Then the following models are calculated:
      | regular_model | get_data.py |
    And the following scripts are ran:
      | regular_model.post_hook.py |
